2021-04-02 18:30:34,437 - [engine.py:774-_internal_run()] - ERROR - Engine run is terminating due to exception: 
